Workbook

Sheet Malayan Banking Stock Price His
A1: Date | B1: Price | C1: 1-year Average Price | D1: Vol. | E1: Change % | F1: Weekly Log Return | G1: Raw Drift | H1: Volatility | I1: Annual Volatility | J1: Market Drift | K1: Average Forecasted Price | L1: Lower Confidence Interval | M1: Upper Confidence Interval | N1: Percentage Error | O1: Average Forecasted Price (Dividend) | P1: Percentage Error (Dividend)
A2: 45139 | B2: 8.86 | D2: 40610000 | E2: 0.0103 | R2: 1. | S2: Maximum | U2: =MAX(B:B) -> 10.80
A3: 01/15/2023 | B3: 8.8 | D3: 53280000 | E3: -0.0068 | F3: =LN(B3/B2) -> -0.68% | S3: Minimum | U3: =MIN(B:B) -> 8.38
A4: 01/22/2023 | B4: 8.74 | D4: 18440000 | E4: -0.0068 | F4: =LN(B4/B3) -> -0.68% | S4: Standard Deviation | U4: =_xlfn.STDEV.P(B:B) -> 0.643884
A5: 01/29/2023 | B5: 8.71 | D5: 47880000 | E5: -0.0034 | F5: =LN(B5/B4) -> -0.34%
A6: 45048 | B6: 8.75 | D6: 37660000 | E6: 0.0046 | F6: =LN(B6/B5) -> 0.46% | R6: 2.
A7: 45262 | B7: 8.75 | D7: 43340000 | E7: 0 | F7: =LN(B7/B6) -> 0.00%
A8: 02/19/2023 | B8: 8.74 | D8: 22050000 | E8: -0.0011 | F8: =LN(B8/B7) -> -0.11%
A9: 02/26/2023 | B9: 8.71 | D9: 49550000 | E9: -0.0034 | F9: =LN(B9/B8) -> -0.34%
A10: 45049 | B10: 8.7 | D10: 48680000 | E10: -0.0011 | F10: =LN(B10/B9) -> -0.11%
A11: 45263 | B11: 8.38 | D11: 57350000 | E11: -0.0368 | F11: =LN(B11/B10) -> -3.75%
A12: 03/19/2023 | B12: 8.43 | D12: 22180000 | E12: 0.006 | F12: =LN(B12/B11) -> 0.59%
A13: 03/26/2023 | B13: 8.57 | D13: 25090000 | E13: 0.0166 | F13: =LN(B13/B12) -> 1.65%
A14: 44961 | B14: 8.66 | D14: 19390000 | E14: 0.0105 | F14: =LN(B14/B13) -> 1.04%
A15: 45173 | B15: 8.71 | D15: 32020000 | E15: 0.0058 | F15: =LN(B15/B14) -> 0.58%
A16: 04/16/2023 | B16: 8.7 | D16: 19050000 | E16: -0.0011 | F16: =LN(B16/B15) -> -0.11%
A17: 04/23/2023 | B17: 8.66 | D17: 27470000 | E17: -0.0046 | F17: =LN(B17/B16) -> -0.46%
A18: 04/30/2023 | B18: 8.75 | D18: 18050000 | E18: 0.0104 | F18: =LN(B18/B17) -> 1.03%
A19: 45112 | B19: 8.69 | D19: 27970000 | E19: -0.0069 | F19: =LN(B19/B18) -> -0.69%
A20: 05/14/2023 | B20: 8.78 | D20: 19660000 | E20: 0.0104 | F20: =LN(B20/B19) -> 1.03%
A21: 05/21/2023 | B21: 8.58 | D21: 42490000 | E21: -0.0228 | F21: =LN(B21/B20) -> -2.30%
A22: 05/28/2023 | B22: 8.58 | D22: 90710000 | E22: 0 | F22: =LN(B22/B21) -> 0.00%
A23: 45022 | B23: 8.62 | D23: 21690000 | E23: 0.0047 | F23: =LN(B23/B22) -> 0.47% | R23: 3. | S23: Assumptions of Geometric Brownian Motion:
A24: 45236 | B24: 8.57 | D24: 39750000 | E24: -0.0058 | F24: =LN(B24/B23) -> -0.58% | S24: • The company is a going concern, and its stock prices are continuous in time and value.
A25: 06/18/2023 | B25: 8.74 | D25: 28970000 | E25: 0.0198 | F25: =LN(B25/B24) -> 1.96% | S25: • Stocks follow a Markov process, meaning only the current stock price is relevant for predicting future prices.
A26: 06/25/2023 | B26: 8.63 | D26: 28300000 | E26: -0.0126 | F26: =LN(B26/B25) -> -1.27% | S26: • The proportional return of a stock is log-normally distributed.
A27: 44964 | B27: 8.67 | D27: 25200000 | E27: 0.0046 | F27: =LN(B27/B26) -> 0.46% | S27: • The continuously compounded return for a stock is normally distributed.
A28: 45176 | B28: 8.8 | D28: 36570000 | E28: 0.015 | F28: =LN(B28/B27) -> 1.49%
A29: 07/16/2023 | B29: 8.78 | D29: 30450000 | E29: -0.0023 | F29: =LN(B29/B28) -> -0.23% | R29: 5. & 6.
A30: 07/23/2023 | B30: 8.99 | D30: 53400000 | E30: 0.0239 | F30: =LN(B30/B29) -> 2.36%
A31: 07/30/2023 | B31: 8.91 | D31: 43640000 | E31: -0.0089 | F31: =LN(B31/B30) -> -0.89%
A32: 45085 | B32: 9.02 | D32: 56960000 | E32: 0.0123 | F32: =LN(B32/B31) -> 1.23%
A33: 08/13/2023 | B33: 9 | D33: 45790000 | E33: -0.0022 | F33: =LN(B33/B32) -> -0.22%
A34: 08/20/2023 | B34: 9.02 | D34: 43680000 | E34: 0.0022 | F34: =LN(B34/B33) -> 0.22%
A35: 08/27/2023 | B35: 9.15 | D35: 45380000 | E35: 0.0144 | F35: =LN(B35/B34) -> 1.43%
A36: 44994 | B36: 9.14 | D36: 36630000 | E36: -0.0011 | F36: =LN(B36/B35) -> -0.11%
A37: 45208 | B37: 8.91 | D37: 59450000 | E37: -0.0252 | F37: =LN(B37/B36) -> -2.55%
A38: 09/17/2023 | B38: 8.88 | D38: 33340000 | E38: -0.0034 | F38: =LN(B38/B37) -> -0.34%
A39: 09/24/2023 | B39: 8.79 | D39: 37510000 | E39: -0.0101 | F39: =LN(B39/B38) -> -1.02%
A40: 44936 | B40: 8.77 | D40: 76250000 | E40: -0.0023 | F40: =LN(B40/B39) -> -0.23%
...

Sheet Forecasted Price
A1: Forecasted price:
A2: Date | B2: 1 | C2: 2 | D2: 3 | E2: 4 | F2: 5 | G2: 6 | H2: 7 | I2: 8 | J2: 9 | K2: 10 | L2: 11 | M2: 12 | N2: 13 | O2: 14 | P2: 15 | Q2: 16 | R2: 17 | S2: 18 | T2: 19 | U2: 20 | V2: 21 | W2: 22 | X2: 23 | Y2: 24 | Z2: 25 | AA2: 26 | AB2: 27 | AC2: 28 | AD2: 29 | AE2: 30 | AF2: 31 | AG2: 32 | AH2: 33 | AI2: 34 | AJ2: 35 | AK2: 36 | AL2: 37 | AM2: 38 | AN2: 39 | AO2: 40 | AP2: 41 | AQ2: 42 | AR2: 43 | AS2: 44 | AT2: 45 | AU2: 46 | AV2: 47 | AW2: 48 | AX2: 49 | AY2: 50 | AZ2: 51 | BA2: 52 | BB2: 53 | BC2: 54 | BD2: 55 | BE2: 56 | BF2: 57 | BG2: 58 | BH2: 59 | BI2: 60 | BJ2: 61 | BK2: 62 | BL2: 63 | BM2: 64 | BN2: 65 | BO2: 66 | BP2: 67 | BQ2: 68 | BR2: 69 | BS2: 70 | BT2: 71 | BU2: 72 | BV2: 73 | BW2: 74 | BX2: 75 | BY2: 76 | BZ2: 77 | CA2: 78 | CB2: 79 | CC2: 80 | CD2: 81 | CE2: 82 | CF2: 83 | CG2: 84 | CH2: 85 | CI2: 86 | CJ2: 87 | CK2: 88 | CL2: 89 | CM2: 90 | CN2: 91 | CO2: 92 | CP2: 93 | CQ2: 94 | CR2: 95 | CS2: 96 | CT2: 97 | CU2: 98 | CV2: 99 | CW2: 100 | CX2: 101 | CY2: 102 | CZ2: 103 | DA2: 104 | DB2: 105 | DC2: 106 | DD2: 107 | DE2: 108 | DF2: 109 | DG2: 110 | DH2: 111 | DI2: 112 | DJ2: 113 | DK2: 114 | DL2: 115 | DM2: 116 | DN2: 117 | DO2: 118 | DP2: 119 | DQ2: 120 | DR2: 121 | DS2: 122 | DT2: 123 | DU2: 124 | DV2: 125 | DW2: 126 | DX2: 127 | DY2: 128 | DZ2: 129 | EA2: 130 | EB2: 131 | EC2: 132 | ED2: 133 | EE2: 134 | EF2: 135 | EG2: 136 | EH2: 137 | EI2: 138 | EJ2: 139 | EK2: 140 | EL2: 141 | EM2: 142 | EN2: 143 | EO2: 144 | EP2: 145 | EQ2: 146 | ER2: 147 | ES2: 148 | ET2: 149 | EU2: 150 | EV2: 151 | EW2: 152 | EX2: 153 | EY2: 154 | EZ2: 155 | FA2: 156 | FB2: 157 | FC2: 158 | FD2: 159 | FE2: 160 | FF2: 161 | FG2: 162 | FH2: 163 | FI2: 164 | FJ2: 165 | FK2: 166 | FL2: 167 | FM2: 168 | FN2: 169 | FO2: 170 | FP2: 171 | FQ2: 172 | FR2: 173 | FS2: 174 | FT2: 175 | FU2: 176 | FV2: 177 | FW2: 178 | FX2: 179 | FY2: 180 | FZ2: 181 | GA2: 182 | GB2: 183 | GC2: 184 | GD2: 185 | GE2: 186 | GF2: 187 | GG2: 188 | GH2: 189 | GI2: 190 | GJ2: 191 | GK2: 192 | GL2: 193 | GM2: 194 | GN2: 195 | GO2: 196 | GP2: 197 | GQ2: 198 | GR2: 199 | GS2: 200 | GT2: 201 | GU2: 202 | GV2: 203 | GW2: 204 | GX2: 205 | GY2: 206 | GZ2: 207 | HA2: 208 | HB2: 209 | HC2: 210 | HD2: 211 | HE2: 212 | HF2: 213 | HG2: 214 | HH2: 215 | HI2: 216 | HJ2: 217 | HK2: 218 | HL2: 219 | HM2: 220 | HN2: 221 | HO2: 222 | HP2: 223 | HQ2: 224 | HR2: 225 | HS2: 226 | HT2: 227 | HU2: 228 | HV2: 229 | HW2: 230 | HX2: 231 | HY2: 232 | HZ2: 233 | IA2: 234 | IB2: 235 | IC2: 236 | ID2: 237 | IE2: 238 | IF2: 239 | IG2: 240 | IH2: 241 | II2: 242 | IJ2: 243 | IK2: 244 | IL2: 245 | IM2: 246 | IN2: 247 | IO2: 248 | IP2: 249 | IQ2: 250 | IR2: 251 | IS2: 252 | IT2: 253 | IU2: 254 | IV2: 255 | IW2: 256 | IX2: 257 | IY2: 258 | IZ2: 259 | JA2: 260 | JB2: 261 | JC2: 262 | JD2: 263 | JE2: 264 | JF2: 265 | JG2: 266 | JH2: 267 | JI2: 268 | JJ2: 269 | JK2: 270 | JL2: 271 | JM2: 272 | JN2: 273 | JO2: 274 | JP2: 275 | JQ2: 276 | JR2: 277 | JS2: 278 | JT2: 279 | JU2: 280 | JV2: 281 | JW2: 282 | JX2: 283 | JY2: 284 | JZ2: 285 | KA2: 286 | KB2: 287 | KC2: 288 | KD2: 289 | KE2: 290 | KF2: 291 | KG2: 292 | KH2: 293 | KI2: 294 | KJ2: 295 | KK2: 296 | KL2: 297 | KM2: 298 | KN2: 299 | KO2: 300 | KP2: 301 | KQ2: 302 | KR2: 303 | KS2: 304 | KT2: 305 | KU2: 306 | KV2: 307 | KW2: 308 | KX2: 309 | KY2: 310 | KZ2: 311 | LA2: 312 | LB2: 313 | LC2: 314 | LD2: 315 | LE2: 316 | LF2: 317 | LG2: 318 | LH2: 319 | LI2: 320 | LJ2: 321 | LK2: 322 | LL2: 323 | LM2: 324 | LN2: 325 | LO2: 326 | LP2: 327 | LQ2: 328 | LR2: 329 | LS2: 330 | LT2: 331 | LU2: 332 | LV2: 333 | LW2: 334 | LX2: 335 | LY2: 336 | LZ2: 337 | MA2: 338 | MB2: 339 | MC2: 340 | MD2: 341 | ME2: 342 | MF2: 343 | MG2: 344 | MH2: 345 | MI2: 346 | MJ2: 347 | MK2: 348 | ML2: 349 | MM2: 350 | MN2: 351 | MO2: 352 | MP2: 353 | MQ2: 354 | MR2: 355 | MS2: 356 | MT2: 357 | MU2: 358 | MV2: 359 | MW2: 360 | MX2: 361 | MY2: 362 | MZ2: 363 | NA2: 364 | NB2: 365 | NC2: 366 | ND2: 367 | NE2: 368 | NF2: 369 | NG2: 370 | NH2: 371 | NI2: 372 | NJ2: 373 | NK2: 374 | NL2: 375 | NM2: 376 | NN2: 377 | NO2: 378 | NP2: 379 | NQ2: 380 | NR2: 381 | NS2: 382 | NT2: 383 | NU2: 384 | NV2: 385 | NW2: 386 | NX2: 387 | NY2: 388 | NZ2: 389 | OA2: 390 | OB2: 391 | OC2: 392 | OD2: 393 | OE2: 394 | OF2: 395 | OG2: 396 | OH2: 397 | OI2: 398 | OJ2: 399 | OK2: 400 | OL2: 401 | OM2: 402 | ON2: 403 | OO2: 404 | OP2: 405 | OQ2: 406 | OR2: 407 | OS2: 408 | OT2: 409 | OU2: 410 | OV2: 411 | OW2: 412 | OX2: 413 | OY2: 414 | OZ2: 415 | PA2: 416 | PB2: 417 | PC2: 418 | PD2: 419 | PE2: 420 | PF2: 421 | PG2: 422 | PH2: 423 | PI2: 424 | PJ2: 425 | PK2: 426 | PL2: 427 | PM2: 428 | PN2: 429 | PO2: 430 | PP2: 431 | PQ2: 432 | PR2: 433 | PS2: 434 | PT2: 435 | PU2: 436 | PV2: 437 | PW2: 438 | PX2: 439 | PY2: 440 | PZ2: 441 | QA2: 442 | QB2: 443 | QC2: 444 | QD2: 445 | QE2: 446 | QF2: 447 | QG2: 448 | QH2: 449 | QI2: 450 | QJ2: 451 | QK2: 452 | QL2: 453 | QM2: 454 | QN2: 455 | QO2: 456 | QP2: 457 | QQ2: 458 | QR2: 459 | QS2: 460 | QT2: 461 | QU2: 462 | QV2: 463 | QW2: 464 | QX2: 465 | QY2: 466 | QZ2: 467 | RA2: 468 | RB2: 469 | RC2: 470 | RD2: 471 | RE2: 472 | RF2: 473 | RG2: 474 | RH2: 475 | RI2: 476 | RJ2: 477 | RK2: 478 | RL2: 479 | RM2: 480 | RN2: 481 | RO2: 482 | RP2: 483 | RQ2: 484 | RR2: 485 | RS2: 486 | RT2: 487 | RU2: 488 | RV2: 489 | RW2: 490 | RX2: 491 | RY2: 492 | RZ2: 493 | SA2: 494 | SB2: 495 | SC2: 496 | SD2: 497 | SE2: 498 | SF2: 499 | SG2: 500
A3: 09/14/2025 | B3: ='Malayan Banking Stock Price His'!$B141*EXP(('Malayan Banking Stock Price His'!$J141/52)+('Malayan Banking Stock Price His'!$I141*SQRT(1/52)*_xlfn.NORM.INV(RAND(),0,1))) -> 9.869929593 | C3: ='Malayan Banking Stock Price His'!$B141*EXP(('Malayan Banking Stock Price His'!$J141/52)+('Malayan Banking Stock Price His'!$I141*SQRT(1/52)*_xlfn.NORM.INV(RAND(),0,1))) -> 9.868379675 | D3: ='Malayan Banking Stock Price His'!$B141*EXP(('Malayan Banking Stock Price His'!$J141/52)+('Malayan Banking Stock Price His'!$I141*SQRT(1/52)*_xlfn.NORM.INV(RAND(),0,1))) -> 9.870225674 | E3: ='Malayan Banking Stock Price His'!$B141*EXP(('Malayan Banking Stock Price His'!$J141/52)+('Malayan Banking Stock Price His'!$I141*SQRT(1/52)*_xlfn.NORM.INV(RAND(),0,1))) -> 9.870945114 | F3: ='Malayan Banking Stock Price His'!$B141*EXP(('Malayan Banking Stock Price His'!$J141/52)+('Malayan Banking Stock Price His'!$I141*SQRT(1/52)*_xlfn.NORM.INV(RAND(),0,1))) -> 9.867670542 | G3: ='Malayan Banking Stock Price His'!$B141*EXP(('Malayan Banking Stock Price His'!$J141/52)+('Malayan Banking Stock Price His'!$I141*SQRT(1/52)*_xlfn.NORM.INV(RAND(),0,1))) -> 9.869036915 | H3: ='Malayan Banking Stock Price His'!$B141*EXP(('Malayan Banking Stock Price His'!$J141/52)+('Malayan Banking Stock Price His'!$I141*SQRT(1/52)*_xlfn.NORM.INV(RAND(),0,1))) -> 9.86454147 | I3: ='Malayan Banking Stock Price His'!$B141*EXP(('Malayan Banking Stock Price His'!$J141/52)+('Malayan Banking Stock Price His'!$I141*SQRT(1/52)*_xlfn.NORM.INV(RAND(),0,1))) -> 9.870772244 | ... SG3: ='Malayan Banking Stock Price His'!$B141*EXP(('Malayan Banking Stock Price His'!$J141/52)+('Malayan Banking Stock Price His'!$I141*SQRT(1/52)*_xlfn.NORM.INV(RAND(),0,1))) -> 9.864128335
A4: 09/21/2025 | B4: ='Malayan Banking Stock Price His'!$B142*EXP(('Malayan Banking Stock Price His'!$J142/52)+('Malayan Banking Stock Price His'!$I142*SQRT(1/52)*_xlfn.NORM.INV(RAND(),0,1))) -> 9.794766291 | C4: ='Malayan Banking Stock Price His'!$B142*EXP(('Malayan Banking Stock Price His'!$J142/52)+('Malayan Banking Stock Price His'!$I142*SQRT(1/52)*_xlfn.NORM.INV(RAND(),0,1))) -> 9.795887386 | D4: ='Malayan Banking Stock Price His'!$B142*EXP(('Malayan Banking Stock Price His'!$J142/52)+('Malayan Banking Stock Price His'!$I142*SQRT(1/52)*_xlfn.NORM.INV(RAND(),0,1))) -> 9.80015587 | E4: ='Malayan Banking Stock Price His'!$B142*EXP(('Malayan Banking Stock Price His'!$J142/52)+('Malayan Banking Stock Price His'!$I142*SQRT(1/52)*_xlfn.NORM.INV(RAND(),0,1))) -> 9.801028993 | F4: ='Malayan Banking Stock Price His'!$B142*EXP(('Malayan Banking Stock Price His'!$J142/52)+('Malayan Banking Stock Price His'!$I142*SQRT(1/52)*_xlfn.NORM.INV(RAND(),0,1))) -> 9.801279818 | G4: ='Malayan Banking Stock Price His'!$B142*EXP(('Malayan Banking Stock Price His'!$J142/52)+('Malayan Banking Stock Price His'!$I142*SQRT(1/52)*_xlfn.NORM.INV(RAND(),0,1))) -> 9.80149218 | H4: ='Malayan Banking Stock Price His'!$B142*EXP(('Malayan Banking Stock Price His'!$J142/52)+('Malayan Banking Stock Price His'!$I142*SQRT(1/52)*_xlfn.NORM.INV(RAND(),0,1))) -> 9.801244641 | I4: ='Malayan Banking Stock Price His'!$B142*EXP(('Malayan Banking Stock Price His'!$J142/52)+('Malayan Banking Stock Price His'!$I142*SQRT(1/52)*_xlfn.NORM.INV(RAND(),0,1))) -> 9.801095261 | ... SG4: ='Malayan Banking Stock Price His'!$B142*EXP(('Malayan Banking Stock Price His'!$J142/52)+('Malayan Banking Stock Price His'!$I142*SQRT(1/52)*_xlfn.NORM.INV(RAND(),0,1))) -> 9.800808658
A5: 09/28/2025 | B5: ='Malayan Banking Stock Price His'!$B143*EXP(('Malayan Banking Stock Price His'!$J143/52)+('Malayan Banking Stock Price His'!$I143*SQRT(1/52)*_xlfn.NORM.INV(RAND(),0,1))) -> 9.88902079 | C5: ='Malayan Banking Stock Price His'!$B143*EXP(('Malayan Banking Stock Price His'!$J143/52)+('Malayan Banking Stock Price His'!$I143*SQRT(1/52)*_xlfn.NORM.INV(RAND(),0,1))) -> 9.890541976 | D5: ='Malayan Banking Stock Price His'!$B143*EXP(('Malayan Banking Stock Price His'!$J143/52)+('Malayan Banking Stock Price His'!$I143*SQRT(1/52)*_xlfn.NORM.INV(RAND(),0,1))) -> 9.891269241 | E5: ='Malayan Banking Stock Price His'!$B143*EXP(('Malayan Banking Stock Price His'!$J143/52)+('Malayan Banking Stock Price His'!$I143*SQRT(1/52)*_xlfn.NORM.INV(RAND(),0,1))) -> 9.88987557 | F5: ='Malayan Banking Stock Price His'!$B143*EXP(('Malayan Banking Stock Price His'!$J143/52)+('Malayan Banking Stock Price His'!$I143*SQRT(1/52)*_xlfn.NORM.INV(RAND(),0,1))) -> 9.893054477 | G5: ='Malayan Banking Stock Price His'!$B143*EXP(('Malayan Banking Stock Price His'!$J143/52)+('Malayan Banking Stock Price His'!$I143*SQRT(1/52)*_xlfn.NORM.INV(RAND(),0,1))) -> 9.888048104 | H5: ='Malayan Banking Stock Price His'!$B143*EXP(('Malayan Banking Stock Price His'!$J143/52)+('Malayan Banking Stock Price His'!$I143*SQRT(1/52)*_xlfn.NORM.INV(RAND(),0,1))) -> 9.890934303 | I5: ='Malayan Banking Stock Price His'!$B143*EXP(('Malayan Banking Stock Price His'!$J143/52)+('Malayan Banking Stock Price His'!$I143*SQRT(1/52)*_xlfn.NORM.INV(RAND(),0,1))) -> 9.887059557 | ... SG5: ='Malayan Banking Stock Price His'!$B143*EXP(('Malayan Banking Stock Price His'!$J143/52)+('Malayan Banking Stock Price His'!$I143*SQRT(1/52)*_xlfn.NORM.INV(RAND(),0,1))) -> 9.891154589
A6: 45787 | B6: ='Malayan Banking Stock Price His'!$B144*EXP(('Malayan Banking Stock Price His'!$J144/52)+('Malayan Banking Stock Price His'!$I144*SQRT(1/52)*_xlfn.NORM.INV(RAND(),0,1))) -> 10.00156248 | C6: ='Malayan Banking Stock Price His'!$B144*EXP(('Malayan Banking Stock Price His'!$J144/52)+('Malayan Banking Stock Price His'!$I144*SQRT(1/52)*_xlfn.NORM.INV(RAND(),0,1))) -> 10.00037714 | D6: ='Malayan Banking Stock Price His'!$B144*EXP(('Malayan Banking Stock Price His'!$J144/52)+('Malayan Banking Stock Price His'!$I144*SQRT(1/52)*_xlfn.NORM.INV(RAND(),0,1))) -> 10.00154444 | E6: ='Malayan Banking Stock Price His'!$B144*EXP(('Malayan Banking Stock Price His'!$J144/52)+('Malayan Banking Stock Price His'!$I144*SQRT(1/52)*_xlfn.NORM.INV(RAND(),0,1))) -> 9.999187962 | F6: ='Malayan Banking Stock Price His'!$B144*EXP(('Malayan Banking Stock Price His'!$J144/52)+('Malayan Banking Stock Price His'!$I144*SQRT(1/52)*_xlfn.NORM.INV(RAND(),0,1))) -> 9.998430678 | G6: ='Malayan Banking Stock Price His'!$B144*EXP(('Malayan Banking Stock Price His'!$J144/52)+('Malayan Banking Stock Price His'!$I144*SQRT(1/52)*_xlfn.NORM.INV(RAND(),0,1))) -> 10.00202617 | H6: ='Malayan Banking Stock Price His'!$B144*EXP(('Malayan Banking Stock Price His'!$J144/52)+('Malayan Banking Stock Price His'!$I144*SQRT(1/52)*_xlfn.NORM.INV(RAND(),0,1))) -> 10.00227341 | I6: ='Malayan Banking Stock Price His'!$B144*EXP(('Malayan Banking Stock Price His'!$J144/52)+('Malayan Banking Stock Price His'!$I144*SQRT(1/52)*_xlfn.NORM.INV(RAND(),0,1))) -> 9.994489249 | ... SG6: ='Malayan Banking Stock Price His'!$B144*EXP(('Malayan Banking Stock Price His'!$J144/52)+('Malayan Banking Stock Price His'!$I144*SQRT(1/52)*_xlfn.NORM.INV(RAND(),0,1))) -> 9.99783784
A7: 46001 | B7: ='Malayan Banking Stock Price His'!$B145*EXP(('Malayan Banking Stock Price His'!$J145/52)+('Malayan Banking Stock Price His'!$I145*SQRT(1/52)*_xlfn.NORM.INV(RAND(),0,1))) -> 9.947858339 | C7: ='Malayan Banking Stock Price His'!$B145*EXP(('Malayan Banking Stock Price His'!$J145/52)+('Malayan Banking Stock Price His'!$I145*SQRT(1/52)*_xlfn.NORM.INV(RAND(),0,1))) -> 9.950774518 | D7: ='Malayan Banking Stock Price His'!$B145*EXP(('Malayan Banking Stock Price His'!$J145/52)+('Malayan Banking Stock Price His'!$I145*SQRT(1/52)*_xlfn.NORM.INV(RAND(),0,1))) -> 9.948272137 | E7: ='Malayan Banking Stock Price His'!$B145*EXP(('Malayan Banking Stock Price His'!$J145/52)+('Malayan Banking Stock Price His'!$I145*SQRT(1/52)*_xlfn.NORM.INV(RAND(),0,1))) -> 9.950229791 | F7: ='Malayan Banking Stock Price His'!$B145*EXP(('Malayan Banking Stock Price His'!$J145/52)+('Malayan Banking Stock Price His'!$I145*SQRT(1/52)*_xlfn.NORM.INV(RAND(),0,1))) -> 9.952352367 | G7: ='Malayan Banking Stock Price His'!$B145*EXP(('Malayan Banking Stock Price His'!$J145/52)+('Malayan Banking Stock Price His'!$I145*SQRT(1/52)*_xlfn.NORM.INV(RAND(),0,1))) -> 9.950298065 | H7: ='Malayan Banking Stock Price His'!$B145*EXP(('Malayan Banking Stock Price His'!$J145/52)+('Malayan Banking Stock Price His'!$I145*SQRT(1/52)*_xlfn.NORM.INV(RAND(),0,1))) -> 9.954343481 | I7: ='Malayan Banking Stock Price His'!$B145*EXP(('Malayan Banking Stock Price His'!$J145/52)+('Malayan Banking Stock Price His'!$I145*SQRT(1/52)*_xlfn.NORM.INV(RAND(),0,1))) -> 9.950987234 | ... SG7: ='Malayan Banking Stock Price His'!$B145*EXP(('Malayan Banking Stock Price His'!$J145/52)+('Malayan Banking Stock Price His'!$I145*SQRT(1/52)*_xlfn.NORM.INV(RAND(),0,1))) -> 9.945443512
A8: 10/19/2025 | B8: ='Malayan Banking Stock Price His'!$B146*EXP(('Malayan Banking Stock Price His'!$J146/52)+('Malayan Banking Stock Price His'!$I146*SQRT(1/52)*_xlfn.NORM.INV(RAND(),0,1))) -> 9.889635757 | C8: ='Malayan Banking Stock Price His'!$B146*EXP(('Malayan Banking Stock Price His'!$J146/52)+('Malayan Banking Stock Price His'!$I146*SQRT(1/52)*_xlfn.NORM.INV(RAND(),0,1))) -> 9.892603189 | D8: ='Malayan Banking Stock Price His'!$B146*EXP(('Malayan Banking Stock Price His'!$J146/52)+('Malayan Banking Stock Price His'!$I146*SQRT(1/52)*_xlfn.NORM.INV(RAND(),0,1))) -> 9.891725437 | E8: ='Malayan Banking Stock Price His'!$B146*EXP(('Malayan Banking Stock Price His'!$J146/52)+('Malayan Banking Stock Price His'!$I146*SQRT(1/52)*_xlfn.NORM.INV(RAND(),0,1))) -> 9.884424739 | F8: ='Malayan Banking Stock Price His'!$B146*EXP(('Malayan Banking Stock Price His'!$J146/52)+('Malayan Banking Stock Price His'!$I146*SQRT(1/52)*_xlfn.NORM.INV(RAND(),0,1))) -> 9.889248305 | G8: ='Malayan Banking Stock Price His'!$B146*EXP(('Malayan Banking Stock Price His'!$J146/52)+('Malayan Banking Stock Price His'!$I146*SQRT(1/52)*_xlfn.NORM.INV(RAND(),0,1))) -> 9.887821523 | H8: ='Malayan Banking Stock Price His'!$B146*EXP(('Malayan Banking Stock Price His'!$J146/52)+('Malayan Banking Stock Price His'!$I146*SQRT(1/52)*_xlfn.NORM.INV(RAND(),0,1))) -> 9.889217776 | I8: ='Malayan Banking Stock Price His'!$B146*EXP(('Malayan Banking Stock Price His'!$J146/52)+('Malayan Banking Stock Price His'!$I146*SQRT(1/52)*_xlfn.NORM.INV(RAND(),0,1))) -> 9.89000207 | ... SG8: ='Malayan Banking Stock Price His'!$B146*EXP(('Malayan Banking Stock Price His'!$J146/52)+('Malayan Banking Stock Price His'!$I146*SQRT(1/52)*_xlfn.NORM.INV(RAND(),0,1))) -> 9.884414714
A9: 10/26/2025 | B9: ='Malayan Banking Stock Price His'!$B147*EXP(('Malayan Banking Stock Price His'!$J147/52)+('Malayan Banking Stock Price His'!$I147*SQRT(1/52)*_xlfn.NORM.INV(RAND(),0,1))) -> 9.898789174 | C9: ='Malayan Banking Stock Price His'!$B147*EXP(('Malayan Banking Stock Price His'!$J147/52)+('Malayan Banking Stock Price His'!$I147*SQRT(1/52)*_xlfn.NORM.INV(RAND(),0,1))) -> 9.898134903 | D9: ='Malayan Banking Stock Price His'!$B147*EXP(('Malayan Banking Stock Price His'!$J147/52)+('Malayan Banking Stock Price His'!$I147*SQRT(1/52)*_xlfn.NORM.INV(RAND(),0,1))) -> 9.904101109 | E9: ='Malayan Banking Stock Price His'!$B147*EXP(('Malayan Banking Stock Price His'!$J147/52)+('Malayan Banking Stock Price His'!$I147*SQRT(1/52)*_xlfn.NORM.INV(RAND(),0,1))) -> 9.90493707 | F9: ='Malayan Banking Stock Price His'!$B147*EXP(('Malayan Banking Stock Price His'!$J147/52)+('Malayan Banking Stock Price His'!$I147*SQRT(1/52)*_xlfn.NORM.INV(RAND(),0,1))) -> 9.904319664 | G9: ='Malayan Banking Stock Price His'!$B147*EXP(('Malayan Banking Stock Price His'!$J147/52)+('Malayan Banking Stock Price His'!$I147*SQRT(1/52)*_xlfn.NORM.INV(RAND(),0,1))) -> 9.901834781 | H9: ='Malayan Banking Stock Price His'!$B147*EXP(('Malayan Banking Stock Price His'!$J147/52)+('Malayan Banking Stock Price His'!$I147*SQRT(1/52)*_xlfn.NORM.INV(RAND(),0,1))) -> 9.900164712 | I9: ='Malayan Banking Stock Price His'!$B147*EXP(('Malayan Banking Stock Price His'!$J147/52)+('Malayan Banking Stock Price His'!$I147*SQRT(1/52)*_xlfn.NORM.INV(RAND(),0,1))) -> 9.907219568 | ... SG9: ='Malayan Banking Stock Price His'!$B147*EXP(('Malayan Banking Stock Price His'!$J147/52)+('Malayan Banking Stock Price His'!$I147*SQRT(1/52)*_xlfn.NORM.INV(RAND(),0,1))) -> 9.896376302
A10: 45699 | B10: ='Malayan Banking Stock Price His'!$B148*EXP(('Malayan Banking Stock Price His'!$J148/52)+('Malayan Banking Stock Price His'!$I148*SQRT(1/52)*_xlfn.NORM.INV(RAND(),0,1))) -> 9.867496964 | C10: ='Malayan Banking Stock Price His'!$B148*EXP(('Malayan Banking Stock Price His'!$J148/52)+('Malayan Banking Stock Price His'!$I148*SQRT(1/52)*_xlfn.NORM.INV(RAND(),0,1))) -> 9.869311935 | D10: ='Malayan Banking Stock Price His'!$B148*EXP(('Malayan Banking Stock Price His'!$J148/52)+('Malayan Banking Stock Price His'!$I148*SQRT(1/52)*_xlfn.NORM.INV(RAND(),0,1))) -> 9.869359407 | E10: ='Malayan Banking Stock Price His'!$B148*EXP(('Malayan Banking Stock Price His'!$J148/52)+('Malayan Banking Stock Price His'!$I148*SQRT(1/52)*_xlfn.NORM.INV(RAND(),0,1))) -> 9.867357597 | F10: ='Malayan Banking Stock Price His'!$B148*EXP(('Malayan Banking Stock Price His'!$J148/52)+('Malayan Banking Stock Price His'!$I148*SQRT(1/52)*_xlfn.NORM.INV(RAND(),0,1))) -> 9.868722522 | G10: ='Malayan Banking Stock Price His'!$B148*EXP(('Malayan Banking Stock Price His'!$J148/52)+('Malayan Banking Stock Price His'!$I148*SQRT(1/52)*_xlfn.NORM.INV(RAND(),0,1))) -> 9.870579584 | H10: ='Malayan Banking Stock Price His'!$B148*EXP(('Malayan Banking Stock Price His'!$J148/52)+('Malayan Banking Stock Price His'!$I148*SQRT(1/52)*_xlfn.NORM.INV(RAND(),0,1))) -> 9.870803183 | I10: ='Malayan Banking Stock Price His'!$B148*EXP(('Malayan Banking Stock Price His'!$J148/52)+('Malayan Banking Stock Price His'!$I148*SQRT(1/52)*_xlfn.NORM.INV(RAND(),0,1))) -> 9.87153081 | ... SG10: ='Malayan Banking Stock Price His'!$B148*EXP(('Malayan Banking Stock Price His'!$J148/52)+('Malayan Banking Stock Price His'!$I148*SQRT(1/52)*_xlfn.NORM.INV(RAND(),0,1))) -> 9.866583349
A11: 45911 | B11: ='Malayan Banking Stock Price His'!$B149*EXP(('Malayan Banking Stock Price His'!$J149/52)+('Malayan Banking Stock Price His'!$I149*SQRT(1/52)*_xlfn.NORM.INV(RAND(),0,1))) -> 9.912602629 | C11: ='Malayan Banking Stock Price His'!$B149*EXP(('Malayan Banking Stock Price His'!$J149/52)+('Malayan Banking Stock Price His'!$I149*SQRT(1/52)*_xlfn.NORM.INV(RAND(),0,1))) -> 9.909999843 | D11: ='Malayan Banking Stock Price His'!$B149*EXP(('Malayan Banking Stock Price His'!$J149/52)+('Malayan Banking Stock Price His'!$I149*SQRT(1/52)*_xlfn.NORM.INV(RAND(),0,1))) -> 9.912413563 | E11: ='Malayan Banking Stock Price His'!$B149*EXP(('Malayan Banking Stock Price His'!$J149/52)+('Malayan Banking Stock Price His'!$I149*SQRT(1/52)*_xlfn.NORM.INV(RAND(),0,1))) -> 9.904982831 | F11: ='Malayan Banking Stock Price His'!$B149*EXP(('Malayan Banking Stock Price His'!$J149/52)+('Malayan Banking Stock Price His'!$I149*SQRT(1/52)*_xlfn.NORM.INV(RAND(),0,1))) -> 9.907438581 | G11: ='Malayan Banking Stock Price His'!$B149*EXP(('Malayan Banking Stock Price His'!$J149/52)+('Malayan Banking Stock Price His'!$I149*SQRT(1/52)*_xlfn.NORM.INV(RAND(),0,1))) -> 9.907588595 | H11: ='Malayan Banking Stock Price His'!$B149*EXP(('Malayan Banking Stock Price His'!$J149/52)+('Malayan Banking Stock Price His'!$I149*SQRT(1/52)*_xlfn.NORM.INV(RAND(),0,1))) -> 9.910246529 | I11: ='Malayan Banking Stock Price His'!$B149*EXP(('Malayan Banking Stock Price His'!$J149/52)+('Malayan Banking Stock Price His'!$I149*SQRT(1/52)*_xlfn.NORM.INV(RAND(),0,1))) -> 9.907865138 | ... SG11: ='Malayan Banking Stock Price His'!$B149*EXP(('Malayan Banking Stock Price His'!$J149/52)+('Malayan Banking Stock Price His'!$I149*SQRT(1/52)*_xlfn.NORM.INV(RAND(),0,1))) -> 9.913659527
A13: Forecasted price with dividend yield:
A14: Date | B14: 1 | C14: 2 | D14: 3 | E14: 4 | F14: 5 | G14: 6 | H14: 7 | I14: 8 | J14: 9 | K14: 10 | L14: 11 | M14: 12 | N14: 13 | O14: 14 | P14: 15 | Q14: 16 | R14: 17 | S14: 18 | T14: 19 | U14: 20 | V14: 21 | W14: 22 | X14: 23 | Y14: 24 | Z14: 25 | AA14: 26 | AB14: 27 | AC14: 28 | AD14: 29 | AE14: 30 | AF14: 31 | AG14: 32 | AH14: 33 | AI14: 34 | AJ14: 35 | AK14: 36 | AL14: 37 | AM14: 38 | AN14: 39 | AO14: 40 | AP14: 41 | AQ14: 42 | AR14: 43 | AS14: 44 | AT14: 45 | AU14: 46 | AV14: 47 | AW14: 48 | AX14: 49 | AY14: 50 | AZ14: 51 | BA14: 52 | BB14: 53 | BC14: 54 | BD14: 55 | BE14: 56 | BF14: 57 | BG14: 58 | BH14: 59 | BI14: 60 | BJ14: 61 | BK14: 62 | BL14: 63 | BM14: 64 | BN14: 65 | BO14: 66 | BP14: 67 | BQ14: 68 | BR14: 69 | BS14: 70 | BT14: 71 | BU14: 72 | BV14: 73 | BW14: 74 | BX14: 75 | BY14: 76 | BZ14: 77 | CA14: 78 | CB14: 79 | CC14: 80 | CD14: 81 | CE14: 82 | CF14: 83 | CG14: 84 | CH14: 85 | CI14: 86 | CJ14: 87 | CK14: 88 | CL14: 89 | CM14: 90 | CN14: 91 | CO14: 92 | CP14: 93 | CQ14: 94 | CR14: 95 | CS14: 96 | CT14: 97 | CU14: 98 | CV14: 99 | CW14: 100 | CX14: 101 | CY14: 102 | CZ14: 103 | DA14: 104 | DB14: 105 | DC14: 106 | DD14: 107 | DE14: 108 | DF14: 109 | DG14: 110 | DH14: 111 | DI14: 112 | DJ14: 113 | DK14: 114 | DL14: 115 | DM14: 116 | DN14: 117 | DO14: 118 | DP14: 119 | DQ14: 120 | DR14: 121 | DS14: 122 | DT14: 123 | DU14: 124 | DV14: 125 | DW14: 126 | DX14: 127 | DY14: 128 | DZ14: 129 | EA14: 130 | EB14: 131 | EC14: 132 | ED14: 133 | EE14: 134 | EF14: 135 | EG14: 136 | EH14: 137 | EI14: 138 | EJ14: 139 | EK14: 140 | EL14: 141 | EM14: 142 | EN14: 143 | EO14: 144 | EP14: 145 | EQ14: 146 | ER14: 147 | ES14: 148 | ET14: 149 | EU14: 150 | EV14: 151 | EW14: 152 | EX14: 153 | EY14: 154 | EZ14: 155 | FA14: 156 | FB14: 157 | FC14: 158 | FD14: 159 | FE14: 160 | FF14: 161 | FG14: 162 | FH14: 163 | FI14: 164 | FJ14: 165 | FK14: 166 | FL14: 167 | FM14: 168 | FN14: 169 | FO14: 170 | FP14: 171 | FQ14: 172 | FR14: 173 | FS14: 174 | FT14: 175 | FU14: 176 | FV14: 177 | FW14: 178 | FX14: 179 | FY14: 180 | FZ14: 181 | GA14: 182 | GB14: 183 | GC14: 184 | GD14: 185 | GE14: 186 | GF14: 187 | GG14: 188 | GH14: 189 | GI14: 190 | GJ14: 191 | GK14: 192 | GL14: 193 | GM14: 194 | GN14: 195 | GO14: 196 | GP14: 197 | GQ14: 198 | GR14: 199 | GS14: 200 | GT14: 201 | GU14: 202 | GV14: 203 | GW14: 204 | GX14: 205 | GY14: 206 | GZ14: 207 | HA14: 208 | HB14: 209 | HC14: 210 | HD14: 211 | HE14: 212 | HF14: 213 | HG14: 214 | HH14: 215 | HI14: 216 | HJ14: 217 | HK14: 218 | HL14: 219 | HM14: 220 | HN14: 221 | HO14: 222 | HP14: 223 | HQ14: 224 | HR14: 225 | HS14: 226 | HT14: 227 | HU14: 228 | HV14: 229 | HW14: 230 | HX14: 231 | HY14: 232 | HZ14: 233 | IA14: 234 | IB14: 235 | IC14: 236 | ID14: 237 | IE14: 238 | IF14: 239 | IG14: 240 | IH14: 241 | II14: 242 | IJ14: 243 | IK14: 244 | IL14: 245 | IM14: 246 | IN14: 247 | IO14: 248 | IP14: 249 | IQ14: 250 | IR14: 251 | IS14: 252 | IT14: 253 | IU14: 254 | IV14: 255 | IW14: 256 | IX14: 257 | IY14: 258 | IZ14: 259 | JA14: 260 | JB14: 261 | JC14: 262 | JD14: 263 | JE14: 264 | JF14: 265 | JG14: 266 | JH14: 267 | JI14: 268 | JJ14: 269 | JK14: 270 | JL14: 271 | JM14: 272 | JN14: 273 | JO14: 274 | JP14: 275 | JQ14: 276 | JR14: 277 | JS14: 278 | JT14: 279 | JU14: 280 | JV14: 281 | JW14: 282 | JX14: 283 | JY14: 284 | JZ14: 285 | KA14: 286 | KB14: 287 | KC14: 288 | KD14: 289 | KE14: 290 | KF14: 291 | KG14: 292 | KH14: 293 | KI14: 294 | KJ14: 295 | KK14: 296 | KL14: 297 | KM14: 298 | KN14: 299 | KO14: 300 | KP14: 301 | KQ14: 302 | KR14: 303 | KS14: 304 | KT14: 305 | KU14: 306 | KV14: 307 | KW14: 308 | KX14: 309 | KY14: 310 | KZ14: 311 | LA14: 312 | LB14: 313 | LC14: 314 | LD14: 315 | LE14: 316 | LF14: 317 | LG14: 318 | LH14: 319 | LI14: 320 | LJ14: 321 | LK14: 322 | LL14: 323 | LM14: 324 | LN14: 325 | LO14: 326 | LP14: 327 | LQ14: 328 | LR14: 329 | LS14: 330 | LT14: 331 | LU14: 332 | LV14: 333 | LW14: 334 | LX14: 335 | LY14: 336 | LZ14: 337 | MA14: 338 | MB14: 339 | MC14: 340 | MD14: 341 | ME14: 342 | MF14: 343 | MG14: 344 | MH14: 345 | MI14: 346 | MJ14: 347 | MK14: 348 | ML14: 349 | MM14: 350 | MN14: 351 | MO14: 352 | MP14: 353 | MQ14: 354 | MR14: 355 | MS14: 356 | MT14: 357 | MU14: 358 | MV14: 359 | MW14: 360 | MX14: 361 | MY14: 362 | MZ14: 363 | NA14: 364 | NB14: 365 | NC14: 366 | ND14: 367 | NE14: 368 | NF14: 369 | NG14: 370 | NH14: 371 | NI14: 372 | NJ14: 373 | NK14: 374 | NL14: 375 | NM14: 376 | NN14: 377 | NO14: 378 | NP14: 379 | NQ14: 380 | NR14: 381 | NS14: 382 | NT14: 383 | NU14: 384 | NV14: 385 | NW14: 386 | NX14: 387 | NY14: 388 | NZ14: 389 | OA14: 390 | OB14: 391 | OC14: 392 | OD14: 393 | OE14: 394 | OF14: 395 | OG14: 396 | OH14: 397 | OI14: 398 | OJ14: 399 | OK14: 400 | OL14: 401 | OM14: 402 | ON14: 403 | OO14: 404 | OP14: 405 | OQ14: 406 | OR14: 407 | OS14: 408 | OT14: 409 | OU14: 410 | OV14: 411 | OW14: 412 | OX14: 413 | OY14: 414 | OZ14: 415 | PA14: 416 | PB14: 417 | PC14: 418 | PD14: 419 | PE14: 420 | PF14: 421 | PG14: 422 | PH14: 423 | PI14: 424 | PJ14: 425 | PK14: 426 | PL14: 427 | PM14: 428 | PN14: 429 | PO14: 430 | PP14: 431 | PQ14: 432 | PR14: 433 | PS14: 434 | PT14: 435 | PU14: 436 | PV14: 437 | PW14: 438 | PX14: 439 | PY14: 440 | PZ14: 441 | QA14: 442 | QB14: 443 | QC14: 444 | QD14: 445 | QE14: 446 | QF14: 447 | QG14: 448 | QH14: 449 | QI14: 450 | QJ14: 451 | QK14: 452 | QL14: 453 | QM14: 454 | QN14: 455 | QO14: 456 | QP14: 457 | QQ14: 458 | QR14: 459 | QS14: 460 | QT14: 461 | QU14: 462 | QV14: 463 | QW14: 464 | QX14: 465 | QY14: 466 | QZ14: 467 | RA14: 468 | RB14: 469 | RC14: 470 | RD14: 471 | RE14: 472 | RF14: 473 | RG14: 474 | RH14: 475 | RI14: 476 | RJ14: 477 | RK14: 478 | RL14: 479 | RM14: 480 | RN14: 481 | RO14: 482 | RP14: 483 | RQ14: 484 | RR14: 485 | RS14: 486 | RT14: 487 | RU14: 488 | RV14: 489 | RW14: 490 | RX14: 491 | RY14: 492 | RZ14: 493 | SA14: 494 | SB14: 495 | SC14: 496 | SD14: 497 | SE14: 498 | SF14: 499 | SG14: 500
A15: 09/14/2025 | B15: ='Malayan Banking Stock Price His'!$B141*EXP((('Malayan Banking Stock Price His'!$J141-(0.6/'Malayan Banking Stock Price His'!$B141))/52)+('Malayan Banking Stock Price His'!$I141*SQRT(1/52)*_xlfn.NORM.INV(RAND(),0,1))) -> 9.854773919 | C15: ='Malayan Banking Stock Price His'!$B141*EXP((('Malayan Banking Stock Price His'!$J141-(0.6/'Malayan Banking Stock Price His'!$B141))/52)+('Malayan Banking Stock Price His'!$I141*SQRT(1/52)*_xlfn.NORM.INV(RAND(),0,1))) -> 9.860500337 | D15: ='Malayan Banking Stock Price His'!$B141*EXP((('Malayan Banking Stock Price His'!$J141-(0.6/'Malayan Banking Stock Price His'!$B141))/52)+('Malayan Banking Stock Price His'!$I141*SQRT(1/52)*_xlfn.NORM.INV(RAND(),0,1))) -> 9.855473692 | E15: ='Malayan Banking Stock Price His'!$B141*EXP((('Malayan Banking Stock Price His'!$J141-(0.6/'Malayan Banking Stock Price His'!$B141))/52)+('Malayan Banking Stock Price His'!$I141*SQRT(1/52)*_xlfn.NORM.INV(RAND(),0,1))) -> 9.858485153 | F15: ='Malayan Banking Stock Price His'!$B141*EXP((('Malayan Banking Stock Price His'!$J141-(0.6/'Malayan Banking Stock Price His'!$B141))/52)+('Malayan Banking Stock Price His'!$I141*SQRT(1/52)*_xlfn.NORM.INV(RAND(),0,1))) -> 9.858124385 | G15: ='Malayan Banking Stock Price His'!$B141*EXP((('Malayan Banking Stock Price His'!$J141-(0.6/'Malayan Banking Stock Price His'!$B141))/52)+('Malayan Banking Stock Price His'!$I141*SQRT(1/52)*_xlfn.NORM.INV(RAND(),0,1))) -> 9.857848455 | H15: ='Malayan Banking Stock Price His'!$B141*EXP((('Malayan Banking Stock Price His'!$J141-(0.6/'Malayan Banking Stock Price His'!$B141))/52)+('Malayan Banking Stock Price His'!$I141*SQRT(1/52)*_xlfn.NORM.INV(RAND(),0,1))) -> 9.861681082 | I15: ='Malayan Banking Stock Price His'!$B141*EXP((('Malayan Banking Stock Price His'!$J141-(0.6/'Malayan Banking Stock Price His'!$B141))/52)+('Malayan Banking Stock Price His'!$I141*SQRT(1/52)*_xlfn.NORM.INV(RAND(),0,1))) -> 9.854413011 | ... SG15: ='Malayan Banking Stock Price His'!$B141*EXP((('Malayan Banking Stock Price His'!$J141-(0.6/'Malayan Banking Stock Price His'!$B141))/52)+('Malayan Banking Stock Price His'!$I141*SQRT(1/52)*_xlfn.NORM.INV(RAND(),0,1))) -> 9.857416862
A16: 09/21/2025 | B16: ='Malayan Banking Stock Price His'!$B142*EXP((('Malayan Banking Stock Price His'!$J142-(0.6/'Malayan Banking Stock Price His'!$B142))/52)+('Malayan Banking Stock Price His'!$I142*SQRT(1/52)*_xlfn.NORM.INV(RAND(),0,1))) -> 9.787190777 | C16: ='Malayan Banking Stock Price His'!$B142*EXP((('Malayan Banking Stock Price His'!$J142-(0.6/'Malayan Banking Stock Price His'!$B142))/52)+('Malayan Banking Stock Price His'!$I142*SQRT(1/52)*_xlfn.NORM.INV(RAND(),0,1))) -> 9.787324795 | D16: ='Malayan Banking Stock Price His'!$B142*EXP((('Malayan Banking Stock Price His'!$J142-(0.6/'Malayan Banking Stock Price His'!$B142))/52)+('Malayan Banking Stock Price His'!$I142*SQRT(1/52)*_xlfn.NORM.INV(RAND(),0,1))) -> 9.784898036 | E16: ='Malayan Banking Stock Price His'!$B142*EXP((('Malayan Banking Stock Price His'!$J142-(0.6/'Malayan Banking Stock Price His'!$B142))/52)+('Malayan Banking Stock Price His'!$I142*SQRT(1/52)*_xlfn.NORM.INV(RAND(),0,1))) -> 9.782850858 | F16: ='Malayan Banking Stock Price His'!$B142*EXP((('Malayan Banking Stock Price His'!$J142-(0.6/'Malayan Banking Stock Price His'!$B142))/52)+('Malayan Banking Stock Price His'!$I142*SQRT(1/52)*_xlfn.NORM.INV(RAND(),0,1))) -> 9.785733924 | G16: ='Malayan Banking Stock Price His'!$B142*EXP((('Malayan Banking Stock Price His'!$J142-(0.6/'Malayan Banking Stock Price His'!$B142))/52)+('Malayan Banking Stock Price His'!$I142*SQRT(1/52)*_xlfn.NORM.INV(RAND(),0,1))) -> 9.786008186 | H16: ='Malayan Banking Stock Price His'!$B142*EXP((('Malayan Banking Stock Price His'!$J142-(0.6/'Malayan Banking Stock Price His'!$B142))/52)+('Malayan Banking Stock Price His'!$I142*SQRT(1/52)*_xlfn.NORM.INV(RAND(),0,1))) -> 9.78726234 | I16: ='Malayan Banking Stock Price His'!$B142*EXP((('Malayan Banking Stock Price His'!$J142-(0.6/'Malayan Banking Stock Price His'!$B142))/52)+('Malayan Banking Stock Price His'!$I142*SQRT(1/52)*_xlfn.NORM.INV(RAND(),0,1))) -> 9.788882411 | ... SG16: ='Malayan Banking Stock Price His'!$B142*EXP((('Malayan Banking Stock Price His'!$J142-(0.6/'Malayan Banking Stock Price His'!$B142))/52)+('Malayan Banking Stock Price His'!$I142*SQRT(1/52)*_xlfn.NORM.INV(RAND(),0,1))) -> 9.787552341
A17: 09/28/2025 | B17: ='Malayan Banking Stock Price His'!$B143*EXP((('Malayan Banking Stock Price His'!$J143-(0.6/'Malayan Banking Stock Price His'!$B143))/52)+('Malayan Banking Stock Price His'!$I143*SQRT(1/52)*_xlfn.NORM.INV(RAND(),0,1))) -> 9.876802896 | C17: ='Malayan Banking Stock Price His'!$B143*EXP((('Malayan Banking Stock Price His'!$J143-(0.6/'Malayan Banking Stock Price His'!$B143))/52)+('Malayan Banking Stock Price His'!$I143*SQRT(1/52)*_xlfn.NORM.INV(RAND(),0,1))) -> 9.878430048 | D17: ='Malayan Banking Stock Price His'!$B143*EXP((('Malayan Banking Stock Price His'!$J143-(0.6/'Malayan Banking Stock Price His'!$B143))/52)+('Malayan Banking Stock Price His'!$I143*SQRT(1/52)*_xlfn.NORM.INV(RAND(),0,1))) -> 9.878757953 | E17: ='Malayan Banking Stock Price His'!$B143*EXP((('Malayan Banking Stock Price His'!$J143-(0.6/'Malayan Banking Stock Price His'!$B143))/52)+('Malayan Banking Stock Price His'!$I143*SQRT(1/52)*_xlfn.NORM.INV(RAND(),0,1))) -> 9.882267434 | F17: ='Malayan Banking Stock Price His'!$B143*EXP((('Malayan Banking Stock Price His'!$J143-(0.6/'Malayan Banking Stock Price His'!$B143))/52)+('Malayan Banking Stock Price His'!$I143*SQRT(1/52)*_xlfn.NORM.INV(RAND(),0,1))) -> 9.877878958 | G17: ='Malayan Banking Stock Price His'!$B143*EXP((('Malayan Banking Stock Price His'!$J143-(0.6/'Malayan Banking Stock Price His'!$B143))/52)+('Malayan Banking Stock Price His'!$I143*SQRT(1/52)*_xlfn.NORM.INV(RAND(),0,1))) -> 9.878768736 | H17: ='Malayan Banking Stock Price His'!$B143*EXP((('Malayan Banking Stock Price His'!$J143-(0.6/'Malayan Banking Stock Price His'!$B143))/52)+('Malayan Banking Stock Price His'!$I143*SQRT(1/52)*_xlfn.NORM.INV(RAND(),0,1))) -> 9.875427053 | I17: ='Malayan Banking Stock Price His'!$B143*EXP((('Malayan Banking Stock Price His'!$J143-(0.6/'Malayan Banking Stock Price His'!$B143))/52)+('Malayan Banking Stock Price His'!$I143*SQRT(1/52)*_xlfn.NORM.INV(RAND(),0,1))) -> 9.880316382 | ... SG17: ='Malayan Banking Stock Price His'!$B143*EXP((('Malayan Banking Stock Price His'!$J143-(0.6/'Malayan Banking Stock Price His'!$B143))/52)+('Malayan Banking Stock Price His'!$I143*SQRT(1/52)*_xlfn.NORM.INV(RAND(),0,1))) -> 9.874915884
A18: 45787 | B18: ='Malayan Banking Stock Price His'!$B144*EXP((('Malayan Banking Stock Price His'!$J144-(0.6/'Malayan Banking Stock Price His'!$B144))/52)+('Malayan Banking Stock Price His'!$I144*SQRT(1/52)*_xlfn.NORM.INV(RAND(),0,1))) -> 9.988043603 | C18: ='Malayan Banking Stock Price His'!$B144*EXP((('Malayan Banking Stock Price His'!$J144-(0.6/'Malayan Banking Stock Price His'!$B144))/52)+('Malayan Banking Stock Price His'!$I144*SQRT(1/52)*_xlfn.NORM.INV(RAND(),0,1))) -> 9.990279352 | D18: ='Malayan Banking Stock Price His'!$B144*EXP((('Malayan Banking Stock Price His'!$J144-(0.6/'Malayan Banking Stock Price His'!$B144))/52)+('Malayan Banking Stock Price His'!$I144*SQRT(1/52)*_xlfn.NORM.INV(RAND(),0,1))) -> 9.988353817 | E18: ='Malayan Banking Stock Price His'!$B144*EXP((('Malayan Banking Stock Price His'!$J144-(0.6/'Malayan Banking Stock Price His'!$B144))/52)+('Malayan Banking Stock Price His'!$I144*SQRT(1/52)*_xlfn.NORM.INV(RAND(),0,1))) -> 9.983115531 | F18: ='Malayan Banking Stock Price His'!$B144*EXP((('Malayan Banking Stock Price His'!$J144-(0.6/'Malayan Banking Stock Price His'!$B144))/52)+('Malayan Banking Stock Price His'!$I144*SQRT(1/52)*_xlfn.NORM.INV(RAND(),0,1))) -> 9.982925442 | G18: ='Malayan Banking Stock Price His'!$B144*EXP((('Malayan Banking Stock Price His'!$J144-(0.6/'Malayan Banking Stock Price His'!$B144))/52)+('Malayan Banking Stock Price His'!$I144*SQRT(1/52)*_xlfn.NORM.INV(RAND(),0,1))) -> 9.986910467 | H18: ='Malayan Banking Stock Price His'!$B144*EXP((('Malayan Banking Stock Price His'!$J144-(0.6/'Malayan Banking Stock Price His'!$B144))/52)+('Malayan Banking Stock Price His'!$I144*SQRT(1/52)*_xlfn.NORM.INV(RAND(),0,1))) -> 9.989546651 | I18: ='Malayan Banking Stock Price His'!$B144*EXP((('Malayan Banking Stock Price His'!$J144-(0.6/'Malayan Banking Stock Price His'!$B144))/52)+('Malayan Banking Stock Price His'!$I144*SQRT(1/52)*_xlfn.NORM.INV(RAND(),0,1))) -> 9.985993441 | ... SG18: ='Malayan Banking Stock Price His'!$B144*EXP((('Malayan Banking Stock Price His'!$J144-(0.6/'Malayan Banking Stock Price His'!$B144))/52)+('Malayan Banking Stock Price His'!$I144*SQRT(1/52)*_xlfn.NORM.INV(RAND(),0,1))) -> 9.990757864
A19: 46001 | B19: ='Malayan Banking Stock Price His'!$B145*EXP((('Malayan Banking Stock Price His'!$J145-(0.6/'Malayan Banking Stock Price His'!$B145))/52)+('Malayan Banking Stock Price His'!$I145*SQRT(1/52)*_xlfn.NORM.INV(RAND(),0,1))) -> 9.939808914 | C19: ='Malayan Banking Stock Price His'!$B145*EXP((('Malayan Banking Stock Price His'!$J145-(0.6/'Malayan Banking Stock Price His'!$B145))/52)+('Malayan Banking Stock Price His'!$I145*SQRT(1/52)*_xlfn.NORM.INV(RAND(),0,1))) -> 9.93667204 | D19: ='Malayan Banking Stock Price His'!$B145*EXP((('Malayan Banking Stock Price His'!$J145-(0.6/'Malayan Banking Stock Price His'!$B145))/52)+('Malayan Banking Stock Price His'!$I145*SQRT(1/52)*_xlfn.NORM.INV(RAND(),0,1))) -> 9.9346712 | E19: ='Malayan Banking Stock Price His'!$B145*EXP((('Malayan Banking Stock Price His'!$J145-(0.6/'Malayan Banking Stock Price His'!$B145))/52)+('Malayan Banking Stock Price His'!$I145*SQRT(1/52)*_xlfn.NORM.INV(RAND(),0,1))) -> 9.936935438 | F19: ='Malayan Banking Stock Price His'!$B145*EXP((('Malayan Banking Stock Price His'!$J145-(0.6/'Malayan Banking Stock Price His'!$B145))/52)+('Malayan Banking Stock Price His'!$I145*SQRT(1/52)*_xlfn.NORM.INV(RAND(),0,1))) -> 9.938299996 | G19: ='Malayan Banking Stock Price His'!$B145*EXP((('Malayan Banking Stock Price His'!$J145-(0.6/'Malayan Banking Stock Price His'!$B145))/52)+('Malayan Banking Stock Price His'!$I145*SQRT(1/52)*_xlfn.NORM.INV(RAND(),0,1))) -> 9.935705992 | H19: ='Malayan Banking Stock Price His'!$B145*EXP((('Malayan Banking Stock Price His'!$J145-(0.6/'Malayan Banking Stock Price His'!$B145))/52)+('Malayan Banking Stock Price His'!$I145*SQRT(1/52)*_xlfn.NORM.INV(RAND(),0,1))) -> 9.938156102 | I19: ='Malayan Banking Stock Price His'!$B145*EXP((('Malayan Banking Stock Price His'!$J145-(0.6/'Malayan Banking Stock Price His'!$B145))/52)+('Malayan Banking Stock Price His'!$I145*SQRT(1/52)*_xlfn.NORM.INV(RAND(),0,1))) -> 9.934239136 | ... SG19: ='Malayan Banking Stock Price His'!$B145*EXP((('Malayan Banking Stock Price His'!$J145-(0.6/'Malayan Banking Stock Price His'!$B145))/52)+('Malayan Banking Stock Price His'!$I145*SQRT(1/52)*_xlfn.NORM.INV(RAND(),0,1))) -> 9.936378371
A20: 10/19/2025 | B20: ='Malayan Banking Stock Price His'!$B146*EXP((('Malayan Banking Stock Price His'!$J146-(0.6/'Malayan Banking Stock Price His'!$B146))/52)+('Malayan Banking Stock Price His'!$I146*SQRT(1/52)*_xlfn.NORM.INV(RAND(),0,1))) -> 9.877395088 | C20: ='Malayan Banking Stock Price His'!$B146*EXP((('Malayan Banking Stock Price His'!$J146-(0.6/'Malayan Banking Stock Price His'!$B146))/52)+('Malayan Banking Stock Price His'!$I146*SQRT(1/52)*_xlfn.NORM.INV(RAND(),0,1))) -> 9.879973057 | D20: ='Malayan Banking Stock Price His'!$B146*EXP((('Malayan Banking Stock Price His'!$J146-(0.6/'Malayan Banking Stock Price His'!$B146))/52)+('Malayan Banking Stock Price His'!$I146*SQRT(1/52)*_xlfn.NORM.INV(RAND(),0,1))) -> 9.875443331 | E20: ='Malayan Banking Stock Price His'!$B146*EXP((('Malayan Banking Stock Price His'!$J146-(0.6/'Malayan Banking Stock Price His'!$B146))/52)+('Malayan Banking Stock Price His'!$I146*SQRT(1/52)*_xlfn.NORM.INV(RAND(),0,1))) -> 9.882308115 | F20: ='Malayan Banking Stock Price His'!$B146*EXP((('Malayan Banking Stock Price His'!$J146-(0.6/'Malayan Banking Stock Price His'!$B146))/52)+('Malayan Banking Stock Price His'!$I146*SQRT(1/52)*_xlfn.NORM.INV(RAND(),0,1))) -> 9.877880998 | G20: ='Malayan Banking Stock Price His'!$B146*EXP((('Malayan Banking Stock Price His'!$J146-(0.6/'Malayan Banking Stock Price His'!$B146))/52)+('Malayan Banking Stock Price His'!$I146*SQRT(1/52)*_xlfn.NORM.INV(RAND(),0,1))) -> 9.871753746 | H20: ='Malayan Banking Stock Price His'!$B146*EXP((('Malayan Banking Stock Price His'!$J146-(0.6/'Malayan Banking Stock Price His'!$B146))/52)+('Malayan Banking Stock Price His'!$I146*SQRT(1/52)*_xlfn.NORM.INV(RAND(),0,1))) -> 9.879222081 | I20: ='Malayan Banking Stock Price His'!$B146*EXP((('Malayan Banking Stock Price His'!$J146-(0.6/'Malayan Banking Stock Price His'!$B146))/52)+('Malayan Banking Stock Price His'!$I146*SQRT(1/52)*_xlfn.NORM.INV(RAND(),0,1))) -> 9.879631824 | ... SG20: ='Malayan Banking Stock Price His'!$B146*EXP((('Malayan Banking Stock Price His'!$J146-(0.6/'Malayan Banking Stock Price His'!$B146))/52)+('Malayan Banking Stock Price His'!$I146*SQRT(1/52)*_xlfn.NORM.INV(RAND(),0,1))) -> 9.882828649
A21: 10/26/2025 | B21: ='Malayan Banking Stock Price His'!$B147*EXP((('Malayan Banking Stock Price His'!$J147-(0.6/'Malayan Banking Stock Price His'!$B147))/52)+('Malayan Banking Stock Price His'!$I147*SQRT(1/52)*_xlfn.NORM.INV(RAND(),0,1))) -> 9.88779059 | C21: ='Malayan Banking Stock Price His'!$B147*EXP((('Malayan Banking Stock Price His'!$J147-(0.6/'Malayan Banking Stock Price His'!$B147))/52)+('Malayan Banking Stock Price His'!$I147*SQRT(1/52)*_xlfn.NORM.INV(RAND(),0,1))) -> 9.887076165 | D21: ='Malayan Banking Stock Price His'!$B147*EXP((('Malayan Banking Stock Price His'!$J147-(0.6/'Malayan Banking Stock Price His'!$B147))/52)+('Malayan Banking Stock Price His'!$I147*SQRT(1/52)*_xlfn.NORM.INV(RAND(),0,1))) -> 9.886653107 | E21: ='Malayan Banking Stock Price His'!$B147*EXP((('Malayan Banking Stock Price His'!$J147-(0.6/'Malayan Banking Stock Price His'!$B147))/52)+('Malayan Banking Stock Price His'!$I147*SQRT(1/52)*_xlfn.NORM.INV(RAND(),0,1))) -> 9.887150019 | F21: ='Malayan Banking Stock Price His'!$B147*EXP((('Malayan Banking Stock Price His'!$J147-(0.6/'Malayan Banking Stock Price His'!$B147))/52)+('Malayan Banking Stock Price His'!$I147*SQRT(1/52)*_xlfn.NORM.INV(RAND(),0,1))) -> 9.890252592 | G21: ='Malayan Banking Stock Price His'!$B147*EXP((('Malayan Banking Stock Price His'!$J147-(0.6/'Malayan Banking Stock Price His'!$B147))/52)+('Malayan Banking Stock Price His'!$I147*SQRT(1/52)*_xlfn.NORM.INV(RAND(),0,1))) -> 9.887787538 | H21: ='Malayan Banking Stock Price His'!$B147*EXP((('Malayan Banking Stock Price His'!$J147-(0.6/'Malayan Banking Stock Price His'!$B147))/52)+('Malayan Banking Stock Price His'!$I147*SQRT(1/52)*_xlfn.NORM.INV(RAND(),0,1))) -> 9.890351216 | I21: ='Malayan Banking Stock Price His'!$B147*EXP((('Malayan Banking Stock Price His'!$J147-(0.6/'Malayan Banking Stock Price His'!$B147))/52)+('Malayan Banking Stock Price His'!$I147*SQRT(1/52)*_xlfn.NORM.INV(RAND(),0,1))) -> 9.891868127 | ... SG21: ='Malayan Banking Stock Price His'!$B147*EXP((('Malayan Banking Stock Price His'!$J147-(0.6/'Malayan Banking Stock Price His'!$B147))/52)+('Malayan Banking Stock Price His'!$I147*SQRT(1/52)*_xlfn.NORM.INV(RAND(),0,1))) -> 9.882023346
A22: 45699 | B22: ='Malayan Banking Stock Price His'!$B148*EXP((('Malayan Banking Stock Price His'!$J148-(0.6/'Malayan Banking Stock Price His'!$B148))/52)+('Malayan Banking Stock Price His'!$I148*SQRT(1/52)*_xlfn.NORM.INV(RAND(),0,1))) -> 9.857227254 | C22: ='Malayan Banking Stock Price His'!$B148*EXP((('Malayan Banking Stock Price His'!$J148-(0.6/'Malayan Banking Stock Price His'!$B148))/52)+('Malayan Banking Stock Price His'!$I148*SQRT(1/52)*_xlfn.NORM.INV(RAND(),0,1))) -> 9.852347374 | D22: ='Malayan Banking Stock Price His'!$B148*EXP((('Malayan Banking Stock Price His'!$J148-(0.6/'Malayan Banking Stock Price His'!$B148))/52)+('Malayan Banking Stock Price His'!$I148*SQRT(1/52)*_xlfn.NORM.INV(RAND(),0,1))) -> 9.855129089 | E22: ='Malayan Banking Stock Price His'!$B148*EXP((('Malayan Banking Stock Price His'!$J148-(0.6/'Malayan Banking Stock Price His'!$B148))/52)+('Malayan Banking Stock Price His'!$I148*SQRT(1/52)*_xlfn.NORM.INV(RAND(),0,1))) -> 9.861902722 | F22: ='Malayan Banking Stock Price His'!$B148*EXP((('Malayan Banking Stock Price His'!$J148-(0.6/'Malayan Banking Stock Price His'!$B148))/52)+('Malayan Banking Stock Price His'!$I148*SQRT(1/52)*_xlfn.NORM.INV(RAND(),0,1))) -> 9.855139731 | G22: ='Malayan Banking Stock Price His'!$B148*EXP((('Malayan Banking Stock Price His'!$J148-(0.6/'Malayan Banking Stock Price His'!$B148))/52)+('Malayan Banking Stock Price His'!$I148*SQRT(1/52)*_xlfn.NORM.INV(RAND(),0,1))) -> 9.858182055 | H22: ='Malayan Banking Stock Price His'!$B148*EXP((('Malayan Banking Stock Price His'!$J148-(0.6/'Malayan Banking Stock Price His'!$B148))/52)+('Malayan Banking Stock Price His'!$I148*SQRT(1/52)*_xlfn.NORM.INV(RAND(),0,1))) -> 9.852294916 | I22: ='Malayan Banking Stock Price His'!$B148*EXP((('Malayan Banking Stock Price His'!$J148-(0.6/'Malayan Banking Stock Price His'!$B148))/52)+('Malayan Banking Stock Price His'!$I148*SQRT(1/52)*_xlfn.NORM.INV(RAND(),0,1))) -> 9.857375405 | ... SG22: ='Malayan Banking Stock Price His'!$B148*EXP((('Malayan Banking Stock Price His'!$J148-(0.6/'Malayan Banking Stock Price His'!$B148))/52)+('Malayan Banking Stock Price His'!$I148*SQRT(1/52)*_xlfn.NORM.INV(RAND(),0,1))) -> 9.861020055
A23: 45911 | B23: ='Malayan Banking Stock Price His'!$B149*EXP((('Malayan Banking Stock Price His'!$J149-(0.6/'Malayan Banking Stock Price His'!$B149))/52)+('Malayan Banking Stock Price His'!$I149*SQRT(1/52)*_xlfn.NORM.INV(RAND(),0,1))) -> 9.899492827 | C23: ='Malayan Banking Stock Price His'!$B149*EXP((('Malayan Banking Stock Price His'!$J149-(0.6/'Malayan Banking Stock Price His'!$B149))/52)+('Malayan Banking Stock Price His'!$I149*SQRT(1/52)*_xlfn.NORM.INV(RAND(),0,1))) -> 9.899278035 | D23: ='Malayan Banking Stock Price His'!$B149*EXP((('Malayan Banking Stock Price His'!$J149-(0.6/'Malayan Banking Stock Price His'!$B149))/52)+('Malayan Banking Stock Price His'!$I149*SQRT(1/52)*_xlfn.NORM.INV(RAND(),0,1))) -> 9.900738303 | E23: ='Malayan Banking Stock Price His'!$B149*EXP((('Malayan Banking Stock Price His'!$J149-(0.6/'Malayan Banking Stock Price His'!$B149))/52)+('Malayan Banking Stock Price His'!$I149*SQRT(1/52)*_xlfn.NORM.INV(RAND(),0,1))) -> 9.894455594 | F23: ='Malayan Banking Stock Price His'!$B149*EXP((('Malayan Banking Stock Price His'!$J149-(0.6/'Malayan Banking Stock Price His'!$B149))/52)+('Malayan Banking Stock Price His'!$I149*SQRT(1/52)*_xlfn.NORM.INV(RAND(),0,1))) -> 9.896314893 | G23: ='Malayan Banking Stock Price His'!$B149*EXP((('Malayan Banking Stock Price His'!$J149-(0.6/'Malayan Banking Stock Price His'!$B149))/52)+('Malayan Banking Stock Price His'!$I149*SQRT(1/52)*_xlfn.NORM.INV(RAND(),0,1))) -> 9.90265656 | H23: ='Malayan Banking Stock Price His'!$B149*EXP((('Malayan Banking Stock Price His'!$J149-(0.6/'Malayan Banking Stock Price His'!$B149))/52)+('Malayan Banking Stock Price His'!$I149*SQRT(1/52)*_xlfn.NORM.INV(RAND(),0,1))) -> 9.90235165 | I23: ='Malayan Banking Stock Price His'!$B149*EXP((('Malayan Banking Stock Price His'!$J149-(0.6/'Malayan Banking Stock Price His'!$B149))/52)+('Malayan Banking Stock Price His'!$I149*SQRT(1/52)*_xlfn.NORM.INV(RAND(),0,1))) -> 9.896278717 | ... SG23: ='Malayan Banking Stock Price His'!$B149*EXP((('Malayan Banking Stock Price His'!$J149-(0.6/'Malayan Banking Stock Price His'!$B149))/52)+('Malayan Banking Stock Price His'!$I149*SQRT(1/52)*_xlfn.NORM.INV(RAND(),0,1))) -> 9.896783969
